Workbook

Sheet тонн
F1: Тонн | G1: Цена | H1: Сумма | I1: Остатка Нурбек
E2: Жами юк | F2: 0 | H2: =+SUM(H4:H19) -> 0 | I2: 77200000
E4: 17,08,2026 | F4: =+F2-SUM(F5:F19) -> 0 | G4: 3720 | H4: =+F4*G4 -> 0 | I4: 10550-15000-8350=7720000
H5: =+F5*G5 -> 0
H6: =+F6*G6 -> 0
H7: =+F7*G7 -> 0
H8: =+F8*G8 -> 0
H9: =+F9*G9 -> 0
H10: =+F10*G10 -> 0
H11: =+F11*G11 -> 0
H12: =+F12*G12 -> 0
H13: =+F13*G13 -> 0
H14: =+F14*G14 -> 0
H15: =+F15*G15 -> 0
H16: =+F16*G16 -> 0
... H19: =+F19*G19 -> 0

Sheet Хитой
A1: Дата | B1: Итог дня
B2: Хитой пул | C2: Ойбек юк | D2: Нурбек тонн | E2: Нурбек Харажат | F2: Фарход тонн | G2: Фарход харажат | H2: Итого | I2: Бригад | J2: Фазли | K2: Нурбек | L2: Лишный расход | M2: Фойда
C3: =+тонн!H2 -> 0 | D3: =+тонн!F2 -> 0
B4: Утган ойдан хитой карзи | C4: 0
A5: 46235 | H5: =+D5+F5 -> 0 | M5: =+C5-E5-G5-I5-J5-K5-L5 -> 0
A6: =+A5+1 -> 46236 | H6: =+D6+F6 -> 0 | M6: =+C6-E6-G6-I6-J6-K6-L6 -> 0
A7: =+A6+1 -> 46237 | H7: =+D7+F7 -> 0 | M7: =+C7-E7-G7-I7-J7-K7-L7 -> 0
A8: =+A7+1 -> 46238 | H8: =+D8+F8 -> 0 | M8: =+C8-E8-G8-I8-J8-K8-L8 -> 0
A9: =+A8+1 -> 46239 | H9: =+D9+F9 -> 0 | M9: =+C9-E9-G9-I9-J9-K9-L9 -> 0
A10: =+A9+1 -> 46240 | H10: =+D10+F10 -> 0 | M10: =+C10-E10-G10-I10-J10-K10-L10 -> 0
A11: =+A10+1 -> 46241 | H11: =+D11+F11 -> 0 | M11: =+C11-E11-G11-I11-J11-K11-L11 -> 0
A12: =+A11+1 -> 46242 | H12: =+D12+F12 -> 0 | M12: =+C12-E12-G12-I12-J12-K12-L12 -> 0
A13: =+A12+1 -> 46243 | H13: =+D13+F13 -> 0 | M13: =+C13-E13-G13-I13-J13-K13-L13 -> 0
A14: =+A13+1 -> 46244 | H14: =+D14+F14 -> 0 | M14: =+C14-E14-G14-I14-J14-K14-L14 -> 0
A15: =+A14+1 -> 46245 | H15: =+D15+F15 -> 0 | M15: =+C15-E15-G15-I15-J15-K15-L15 -> 0
A16: =+A15+1 -> 46246 | H16: =+D16+F16 -> 0 | M16: =+C16-E16-G16-I16-J16-K16-L16 -> 0
A17: =+A16+1 -> 46247 | H17: =+D17+F17 -> 0 | M17: =+C17-E17-G17-I17-J17-K17-L17 -> 0
... A35: =+A34+1 -> 46265 | H35: =+D35+F35 -> 0 | M35: =+C35-E35-G35-I35-J35-K35-L35 -> 0
B36: =+SUM(B3:B35) -> 0 | C36: =+SUM(C4:C35) -> 0 | D36: =+SUM(D5:D35) -> 0 | E36: =+SUM(E5:E35) -> 0 | F36: =+SUM(F3:F35) -> 0 | G36: =+SUM(G3:G35) -> 0 | H36: =+SUM(H3:H35) -> 0 | I36: =+SUM(I3:I35) -> 0 | J36: =+SUM(J3:J35) -> 0 | K36: =+SUM(K3:K35) -> 0 | L36: =+SUM(L3:L35) -> 0 | M36: =+SUM(M3:M35) -> 0
B38: Хитой | C38: =+B36-C36 -> 0
B39: Ойбек | C39: =+C36-B36 -> 0
B40: Тоннаж | C40: =+H36 -> 0
B41: Фойда | C41: =+M36 -> 0
B43: Ойбек | C43: =+C36 -> 0
B44: Нурбек харид | C44: =+E36 -> 0
B45: Бригад | C45: =+I36 -> 0
B46: Фазли | C46: =+J36 -> 0
B47: Лишный расход | C47: =+L36 -> 0
B48: Нурбек ойлик | C48: =+K36 -> 0
B49: Хитой итого долг | C49: =+C50+C39 -> 0
B50: Хитой бонус | C50: =+C40*100 -> 0
B51: Соф фойда | C51: =+C50+C41 -> 0
B52: ИКРОМ | C52: =+C40*20 -> 0
C53: =+C41*20 -> 0
C54: =+C42*20 -> 0
C55: =+C43*20 -> 0
C56: =+C44*20 -> 0
B58: Итого | C58: =+C51-C52-C53-C54-C55-C56-C57 -> 0
B59: Ойбек | C59: =+C58/3 -> 0
B60: Тура ака | C60: =+C58/3 -> 0
...

Sheet тура ака
A1: Дата | B1: Ойбек Пул берди | C1: Тура ака Пул берди | D1: Нима учун берди | E1: Номер машини | F1: Брутто | G1: Тара | H1: Нетто | I1: % скидка | J1: Чистый | K1: Цена | L1: сумма Металл | M1: Ойбек пул берди | N1: =+N2+B3 -> 1.1849354e+09 | P1: Ойбек пул | Q1: Фойда
M2: Ойбек | N2: =+L3-C3 -> 7.2443744e+08
B3: =+SUM(B4:B9995) -> 460497948 | C3: =+SUM(C4:C9995) -> 24681400060 | F3: =+SUM(F4:F9995) -> 13815660 | G3: =+SUM(G4:G9995) -> 6833940 | H3: =+SUM(H4:H9995) -> 6981720 | J3: =+SUM(J4:J9995) -> 6828721.2 | L3: =+SUM(L4:L9995)+857286788 -> 2.5405838e+10 | M3: Тура | N3: =+C3-L3-B3 -> -1.1849354e+09
A4: 01,02,2026 | C4: 955000 | D4: 834 зарар | E4: 966 бекобод | F4: 27180 | G4: 13460 | H4: =+F4-G4 -> 13720 | I4: 3 | J4: =+H4-H4*I4/100 -> 13308.4 | K4: 3350 | L4: =+J4*K4 -> 44583140
C5: 120000000 | D5: сум | E5: 004 тур мяхки | F5: 22050 | G5: 9970 | H5: =+F5-G5 -> 12080 | I5: 2 | J5: =+H5-H5*I5/100 -> 11838.4 | K5: 3650 | L5: =+J5*K5 -> 43210160
C6: 36065000 | D6: хитой чермет | H6: =+F6-G6 -> 0 | J6: =+H6-H6*I6/100 -> 0 | L6: =+J6*K6 -> 0
A7: 2,02,2026 | C7: 242000000 | D7: икром симентчи | E7: 264 мяхки нов | F7: 23140 | G7: 10880 | H7: =+F7-G7 -> 12260 | I7: 2 | J7: =+H7-H7*I7/100 -> 12014.8 | K7: 3650 | L7: =+J7*K7 -> 43854020
E8: 388 релс | F8: 30000 | G8: 10170 | H8: =+F8-G8 -> 19830 | J8: =+H8-H8*I8/100 -> 19830 | K8: 3650 | L8: =+J8*K8 -> 72379500
E9: 142 релс | F9: 39910 | G9: 13310 | H9: =+F9-G9 -> 26600 | J9: =+H9-H9*I9/100 -> 26600 | K9: 3650 | L9: =+J9*K9 -> 97090000
E10: 130 релс | F10: 26720 | G10: 9580 | H10: =+F10-G10 -> 17140 | J10: =+H10-H10*I10/100 -> 17140 | K10: 3650 | L10: =+J10*K10 -> 62561000
C11: 3370000 | D11: 266 зарар+++ | E11: 884 чугун бекобод | F11: 37120 | G11: 13380 | H11: =+F11-G11 -> 23740 | I11: 2 | J11: =+H11-H11*I11/100 -> 23265.2 | K11: 3350 | L11: =+J11*K11 -> 77938420
A12: 3,02,2026 | E12: 365 бекобод | F12: 26180 | G12: 12980 | H12: =+F12-G12 -> 13200 | I12: 2 | J12: =+H12-H12*I12/100 -> 12936 | K12: 3350 | L12: =+J12*K12 -> 43335600
E13: 377 бозор чирчик | F13: 25480 | G13: 9460 | H13: =+F13-G13 -> 16020 | I13: 1 | J13: =+H13-H13*I13/100 -> 15859.8 | K13: 3650 | L13: =+J13*K13 -> 57888270
E14: 904 мяхки йул кир | F14: 15920 | G14: 9140 | H14: =+F14-G14 -> 6780 | I14: 2 | J14: =+H14-H14*I14/100 -> 6644.4 | K14: 3900 | L14: =+J14*K14 -> 25913160
C15: =650*3650 -> 2372500 | D15: 011 зарар | H15: =+F15-G15 -> 0 | J15: =+H15-H15*I15/100 -> 0 | L15: =+J15*K15 -> 0
A16: 4,03,2026 | C16: =40000*12250 -> 490000000 | D16: 40,000 $$ | E16: 725 мяхки ислом | F16: 10790 | G16: 4900 | H16: =+F16-G16 -> 5890 | I16: 2 | J16: =+H16-H16*I16/100 -> 5772.2 | K16: 3900 | L16: =+J16*K16 -> 22511580
E17: 074 когон мяхки | F17: 25400 | G17: 11160 | H17: =+F17-G17 -> 14240 | I17: 2 | J17: =+H17-H17*I17/100 -> 13955.2 | K17: 3600 | L17: =+J17*K17 -> 50238720
C18: 300000 | D18: 800-500=300 низ | E18: 445 мяхки низом | F18: 23820 | G18: 9240 | H18: =+F18-G18 -> 14580 | I18: 2 | J18: =+H18-H18*I18/100 -> 14288.4 | K18: 3650 | L18: =+J18*K18 -> 52152660
C19: 300000 | D19: 574 шофир | E19: 574 бобир бекобод | F19: 24980 | G19: 12900 | H19: =+F19-G19 -> 12080 | I19: 3 | J19: =+H19-H19*I19/100 -> 11717.6 | K19: 3350 | L19: =+J19*K19 -> 39253960
E20: 463 бобр мяхк | F20: 25120 | G20: 9960 | H20: =+F20-G20 -> 15160 | I20: 1 | J20: =+H20-H20*I20/100 -> 15008.4 | K20: 3650 | L20: =+J20*K20 -> 54780660
E21: 593 мяхки комил | F21: 21980 | G21: 12750 | H21: =+F21-G21 -> 9230 | I21: 2 | J21: =+H21-H21*I21/100 -> 9045.4 | K21: 3650 | L21: =+J21*K21 -> 33015710
E22: 597 тур мяхки | F22: 25530 | G22: 11460 | H22: =+F22-G22 -> 14070 | I22: 2 | J22: =+H22-H22*I22/100 -> 13788.6 | K22: 3650 | L22: =+J22*K22 -> 50328390
C23: 325000 | D23: 413 мошин | E23: 413 бекобод | F23: 25520 | G23: 14820 | H23: =+F23-G23 -> 10700 | I23: 3 | J23: =+H23-H23*I23/100 -> 10379 | K23: 3350 | L23: =+J23*K23 -> 34769650
A24: 5,02,2026 | C24: =10000*12250 -> 122500000 | E24: 145 мяхки исл | F24: 10580 | G24: 5160 | H24: =+F24-G24 -> 5420 | I24: 2 | J24: =+H24-H24*I24/100 -> 5311.6 | K24: 3900 | L24: =+J24*K24 -> 20715240
E25: 437 мяхки исл | F25: 9500 | G25: 4670 | H25: =+F25-G25 -> 4830 | I25: 2 | J25: =+H25-H25*I25/100 -> 4733.4 | K25: 3900 | L25: =+J25*K25 -> 18460260
C26: 380000 | D26: 593 шофир | E26: 562 ром мяхки | F26: 29400 | G26: 9800 | H26: =+F26-G26 -> 19600 | I26: 2 | J26: =+H26-H26*I26/100 -> 19208 | K26: 3650 | L26: =+J26*K26 -> 70109200
C27: 700000 | D27: 032 шофир | E27: 032 еко бекобод | F27: 24080 | G27: 14040 | H27: =+F27-G27 -> 10040 | I27: 3.6 | J27: =+H27-H27*I27/100 -> 9678.56 | K27: 3350 | L27: =+J27*K27 -> 32423176
A28: 6,02,2026 | C28: =16000*12270 -> 196320000 | D28: 16000$ | E28: 996 ТУР МЯХКИ | F28: 22200 | G28: 9830 | H28: =+F28-G28 -> 12370 | I28: 2 | J28: =+H28-H28*I28/100 -> 12122.6 | K28: 3650 | L28: =+J28*K28 -> 44247490 | P28: 43100000 | Q28: =+L28-P28 -> 1147490
E29: 384 бекобод | F29: 26520 | G29: 13300 | H29: =+F29-G29 -> 13220 | I29: 2.6 | J29: =+H29-H29*I29/100 -> 12876.28 | K29: 3350 | L29: =+J29*K29 -> 43135538 | P29: 42474000 | Q29: =+L29-P29 -> 661538
C30: 645000 | D30: 537 мошин учун | E30: 537 мяхки комил | F30: 17620 | G30: 10200 | H30: =+F30-G30 -> 7420 | I30: 2 | J30: =+H30-H30*I30/100 -> 7271.6 | K30: 3650 | L30: =+J30*K30 -> 26541340 | P30: 25645000 | Q30: =+L30-P30 -> 896340
C31: 365000 | D31: 377 мошин учун | E31: 377 мяхки рометан | F31: 17940 | G31: 9400 | H31: =+F31-G31 -> 8540 | I31: 2 | J31: =+H31-H31*I31/100 -> 8369.2 | K31: 3650 | L31: =+J31*K31 -> 30547580 | P31: 29525000 | Q31: =+L31-P31 -> 1022580
E32: 714 бекобод жамил | F32: 32900 | G32: 12460 | H32: =+F32-G32 -> 20440 | I32: 2.5 | J32: =+H32-H32*I32/100 -> 19929 | K32: 3350 | L32: =+J32*K32 -> 66762150 | P32: 64753000 | Q32: =+L32-P32 -> 2009150
C33: 1267000 | D33: 074 зарар | H33: =+F33-G33 -> 0 | J33: =+H33-H33*I33/100 -> 0 | L33: =+J33*K33 -> 0 | Q33: =+L33-P33 -> 0
C34: 858000 | D34: 445 зарар | H34: =+F34-G34 -> 0 | J34: =+H34-H34*I34/100 -> 0 | L34: =+J34*K34 -> 0 | Q34: =+L34-P34 -> 0
A35: 7,02,2026 | C35: =15000*12280 -> 184200000 | D35: 15000$$ | E35: 999 бекобод жамил | F35: 23900 | G35: 11000 | H35: =+F35-G35 -> 12900 | I35: 2 | J35: =+H35-H35*I35/100 -> 12642 | K35: 3350 | L35: =+J35*K35 -> 42350700 | P35: 41500000 | Q35: =+L35-P35 -> 850700
E36: 698 мяхк ислом | F36: 11160 | G36: 5020 | H36: =+F36-G36 -> 6140 | I36: 2 | J36: =+H36-H36*I36/100 -> 6017.2 | K36: 3900 | L36: =+J36*K36 -> 23467080 | P36: 22632000 | Q36: =+L36-P36 -> 835080
H37: =+F37-G37 -> 0 | J37: =+H37-H37*I37/100 -> 0 | L37: =+J37*K37 -> 0 | Q37: =+L37-P37 -> 0
C38: =288*3900 -> 1123200 | D38: 288 кг 463 мошин | H38: =+F38-G38 -> 0 | J38: =+H38-H38*I38/100 -> 0 | L38: =+J38*K38 -> 0 | Q38: =+L38-P38 -> 0
C39: =133*3900 -> 518700 | D39: 133кг 437 мошин | H39: =+F39-G39 -> 0 | J39: =+H39-H39*I39/100 -> 0 | L39: =+J39*K39 -> 0 | Q39: =+L39-P39 -> 0
C40: =278*3900 -> 1084200 | D40: 278 кг 562 мошин | H40: =+F40-G40 -> 0 | J40: =+H40-H40*I40/100 -> 0 | L40: =+J40*K40 -> 0 | Q40: =+L40-P40 -> 0
...

Sheet дафтарча
B2: Дата | C2: Сабаб | D2: Ойбек | E2: Мошин номер | F2: Брутто | G2: Нетто | H2: ТОНН | I2: Скидка | J2: Цена | K2: Феруз укаси
D3: =+SUM(D4:D46) -> 0 | H3: =+SUM(H4:H46) -> 4910 | K3: =+SUM(K4:K46) -> 17013150 | L3: Ойбек пул берди | M3: =+D3 -> 0
B4: 01,09,26 | E4: 919 | F4: 18800 | G4: 13890 | H4: =+F4-G4 -> 4910 | I4: 1 | J4: 3500 | K4: =+(H4-H4*I4/100)*J4 -> 17013150 | L4: =+K2 -> Феруз укаси | M4: =+K3 -> 17013150
H5: =+F5-G5 -> 0 | K5: =+(H5-H5*I5/100)*J5 -> 0 | L5: Делта | M5: =+M3-M4 -> -17013150
H6: =+F6-G6 -> 0 | K6: =+(H6-H6*I6/100)*J6 -> 0
H7: =+F7-G7 -> 0 | K7: =+(H7-H7*I7/100)*J7 -> 0
H8: =+F8-G8 -> 0 | K8: =+(H8-H8*I8/100)*J8 -> 0
H9: =+F9-G9 -> 0 | K9: =+(H9-H9*I9/100)*J9 -> 0
H10: =+F10-G10 -> 0 | K10: =+(H10-H10*I10/100)*J10 -> 0
H11: =+F11-G11 -> 0 | K11: =+(H11-H11*I11/100)*J11 -> 0
H12: =+F12-G12 -> 0 | K12: =+(H12-H12*I12/100)*J12 -> 0
H13: =+F13-G13 -> 0 | K13: =+(H13-H13*I13/100)*J13 -> 0
H14: =+F14-G14 -> 0 | K14: =+(H14-H14*I14/100)*J14 -> 0
H15: =+F15-G15 -> 0 | K15: =+(H15-H15*I15/100)*J15 -> 0
H16: =+F16-G16 -> 0 | K16: =+(H16-H16*I16/100)*J16 -> 0
H17: =+F17-G17 -> 0 | K17: =+(H17-H17*I17/100)*J17 -> 0
... H46: =+F46-G46 -> 0 | K46: =+(H46-H46*I46/100)*J46 -> 0
B57: Дата | C57: Сабаб | D57: Ойбек | E57: Мошин номер | F57: Брутто | G57: Нетто | H57: ТОНН | I57: Скидка | J57: Цена | K57: шамсилло
D58: =+SUM(D59:D107) -> 223288000 | H58: =+SUM(H59:H107) -> 60780 | K58: =+SUM(K59:K107) -> 211472295 | L58: Ойбек пул берди | M58: =+D58 -> 223288000
B59: 28,08,2026 | C59: 886 мош 190 кг | D59: =190*3200 -> 608000 | H59: =+F59-G59 -> 0 | K59: =+(H59-H59*I59/100)*J59 -> 0 | L59: =+K57 -> шамсилло | M59: =+K58 -> 211472295
B60: 28,08,2026 | C60: 4000 | D60: =4000*11825 -> 47300000 | H60: =+F60-G60 -> 0 | K60: =+(H60-H60*I60/100)*J60 -> 0 | L60: Делта | M60: =+M58-M59 -> 11815705
B61: 29,08,2026 | C61: 5000 | D61: =5000*11850 -> 59250000 | E61: 467 | F61: 22310 | G61: 12990 | H61: =+F61-G61 -> 9320 | I61: 0.5 | J61: 3750 | K61: =+(H61-H61*I61/100)*J61 -> 34775250
E62: 834 | F62: 24090 | G62: 12580 | H62: =+F62-G62 -> 11510 | I62: 3 | J62: 3600 | K62: =+(H62-H62*I62/100)*J62 -> 40192920
B63: 30,08,2026 | E63: 576 | F63: 13040 | G63: 9310 | H63: =+F63-G63 -> 3730 | I63: 1 | J63: 3750 | K63: =+(H63-H63*I63/100)*J63 -> 13847625
B64: 31,08,2026 | C64: 3800 | D64: =3800*11850 -> 45030000 | E64: 886 | F64: 26040 | G64: 12900 | H64: =+F64-G64 -> 13140 | I64: 3 | J64: 3300 | K64: =+(H64-H64*I64/100)*J64 -> 42061140
E65: 773 | F65: 28730 | G65: 14730 | H65: =+F65-G65 -> 14000 | I65: 3 | J65: 3600 | K65: =+(H65-H65*I65/100)*J65 -> 48888000
E66: 267 | F66: 17450 | G66: 8370 | H66: =+F66-G66 -> 9080 | I66: 3 | J66: 3600 | K66: =+(H66-H66*I66/100)*J66 -> 31707360
B67: 01,09,26 | C67: 6000 | D67: =6000*11850 -> 71100000 | H67: =+F67-G67 -> 0 | K67: =+(H67-H67*I67/100)*J67 -> 0
H68: =+F68-G68 -> 0 | K68: =+(H68-H68*I68/100)*J68 -> 0
H69: =+F69-G69 -> 0 | K69: =+(H69-H69*I69/100)*J69 -> 0
H70: =+F70-G70 -> 0 | K70: =+(H70-H70*I70/100)*J70 -> 0
H71: =+F71-G71 -> 0 | K71: =+(H71-H71*I71/100)*J71 -> 0
H72: =+F72-G72 -> 0 | K72: =+(H72-H72*I72/100)*J72 -> 0
H73: =+F73-G73 -> 0 | K73: =+(H73-H73*I73/100)*J73 -> 0
H74: =+F74-G74 -> 0 | K74: =+(H74-H74*I74/100)*J74 -> 0
H75: =+F75-G75 -> 0 | K75: =+(H75-H75*I75/100)*J75 -> 0
H76: =+F76-G76 -> 0 | K76: =+(H76-H76*I76/100)*J76 -> 0
H77: =+F77-G77 -> 0 | K77: =+(H77-H77*I77/100)*J77 -> 0
H78: =+F78-G78 -> 0 | K78: =+(H78-H78*I78/100)*J78 -> 0
H79: =+F79-G79 -> 0 | K79: =+(H79-H79*I79/100)*J79 -> 0
...

Sheet Кунлик
A1: № | C1: $ | D1: А ман карз | E1: Ман Карз
D2: =+SUM(D5:D10037) -> 301869165 | E2: =+SUM(E5:E10037) -> 1.2599641e+09 | F2: Кунлик | G2: =D2-E2 -> -9.5809495e+08
F3: Приход-расход | G3: =+'Приход-Расход'!C2 -> -9.5809495e+08
F4: Делта | G4: =+G2-G3 -> 2.1457672e-06
A5: 1 | B5: Ойбек - Тура ака | E5: =+'тура ака'!N3 -> -1.1849354e+09
A6: =+A5+1 -> 2 | B6: Хитой | E6: =+Хитой!C38 -> 0 | F6: Корхоно | G6: =+Каракул!D56*-1 -> -141473600
A7: =+A6+1 -> 3 | B7: Хитой фойда | E7: =+Хитой!C41 -> 0 | F7: Итого уйиндан карз | G7: =+G6+G3+17010000 -> -1.0825585e+09 | H7: =+G7/12000 -> -90213.212
A8: =+A7+1 -> 4 | B8: Нурбек кунлик | E8: =+Хитой!C48 -> 0 | F8: Гостиница | G8: =+Гостиница!C3 -> 0
A9: =+A8+1 -> 5 | B9: Раим Пул | D9: =+Рахим!B18 -> 72520000
A10: =+A9+1 -> 6 | B10: Раим товар | D10: =Рахим!B19 -> 37320000 | E10: =+Рахим!B17 -> 3439500 | F10: Утган ой да карз | G10: 1082558547
A11: =+A10+1 -> 7 | B11: Чермет бонус | E11: =+'Чермт Бонус'!H4 -> 0 | F11: Делта | G11: =+G10+G7 -> 0.42600036
A12: =+A11+1 -> 8 | B12: Иззат | D12: =+Рахим!M2 -> 101446000 | F12: Итого | G12: =+G8+G11 -> 0.42600036
A13: =+A12+1 -> 9 | B13: =+Рахим!T1 -> рахим киленти янги | D13: =+Рахим!R2 -> 0
A14: =+A13+1 -> 10 | B14: наим тогом | D14: =+тогом!A2 -> -14976200
A15: =+A14+1 -> 11 | B15: =+тонн!I1 -> Остатка Нурбек | D15: =+тонн!I2 -> 77200000
A16: 10 | B16: =+дафтарча!K2 -> Феруз укаси | D16: =+дафтарча!M5 -> -17013150
A17: =+A16+1 -> 11 | B17: =+Бонусча!G2 -> Хитой бонусча | D17: =+Бонусча!I7 -> 0
A18: =+A17+1 -> 12 | B18: =+дафтарча!K57 -> шамсилло | D18: =+дафтарча!M60 -> 11815705
A19: =+A18+1 -> 13 | B19: =+дафтарча!K110 -> сает | D19: =+дафтарча!M113 -> 10000000
A20: =+A19+1 -> 14 | B20: =+дафтарча!K134 -> хасан | D20: =+дафтарча!M137 -> 19351500 | F20: Кунлик | G20: =+SUM(D16:D68) -> -157740135
A21: =+A20+1 -> 15 | B21: =+дафтарча!K155 -> мехри вобкент | D21: =+дафтарча!M158 -> -3465750 | F21: Дафтарча | G21: =+дафтарча!P4+Бонусча!I7 -> 0
A22: =+A21+1 -> 16 | B22: =+дафтарча!K169 -> мавлон | D22: =+дафтарча!M172 -> -23990970 | F22: Делта | G22: =+G20-G21 -> -157740135
A23: =+A22+1 -> 17 | B23: =+дафтарча!K185 -> бобир того | D23: =+дафтарча!M188 -> -26935550
A24: =+A23+1 -> 18 | B24: =+дафтарча!K204 -> сироч ака 20 тн | D24: =+дафтарча!M207 -> -60000000
A25: =+A24+1 -> 19 | B25: =+дафтарча!K218 -> САРДОР | D25: =+дафтарча!M221 -> -254600
A26: =+A25+1 -> 20 | B26: =+дафтарча!K247 -> али, | D26: =+дафтарча!M250 -> 14280000
A27: =+A26+1 -> 21 | B27: =+дафтарча!K265 -> одил ака | D27: =+дафтарча!M268 -> 2825000
A28: =+A27+1 -> 22 | B28: =+дафтарча!K277 -> фармон | D28: =+дафтарча!M280 -> 8130000
A29: =+A28+1 -> 23 | B29: =+дафтарча!K294 -> Достон пешку | D29: =+дафтарча!M297 -> -33340000
A30: =+A29+1 -> 24 | B30: =+дафтарча!K321 -> истат | D30: =+дафтарча!M324 -> -42537320
A31: =+A30+1 -> 25 | B31: =+дафтарча!K338 -> сироч еко | D31: =+дафтарча!M341 -> -20160000
A32: =+A31+1 -> 26 | B32: =+дафтарча!K378 -> запас | D32: =+дафтарча!M381 -> 0
A33: =+A32+1 -> 27 | B33: =+дафтарча!K392 -> запас | D33: =+дафтарча!M395 -> 0
A34: =+A33+1 -> 28 | B34: =+дафтарча!K406 -> запас | D34: =+дафтарча!M409 -> 0
A35: =+A34+1 -> 29 | B35: =+дафтарча!K427 -> запас | D35: =+дафтарча!M430 -> 0
A36: =+A35+1 -> 30 | B36: =+дафтарча!K441 -> запас | D36: =+дафтарча!M444 -> 0
A37: =+A36+1 -> 31 | B37: =+дафтарча!K455 -> запас | D37: =+дафтарча!M458 -> 0
A38: =+A37+1 -> 32 | B38: =+дафтарча!K469 -> запас | D38: =+дафтарча!M472 -> 0
A39: =+A38+1 -> 33 | B39: =+дафтарча!K493 -> запас | D39: =+дафтарча!M496 -> 0
A40: =+A39+1 -> 34 | B40: =+дафтарча!K506 -> запас | D40: =+дафтарча!M509 -> 0
...

Sheet Приход-Расход
A1: Дата | B1: Расход сумма | C1: Расход Наименование | D1: Дата | E1: Приход сумма | F1: Приход Наименование
C2: =+E3-B3 -> -9.5809495e+08 | D2: =+C2/12150 -> -78855.551 | G2: Расход | H2: =+B3 -> 2905398055 | I2: 87,280 $
B3: =+SUM(B4:B9995) -> 2905398055 | C3: 342442112 | E3: =+SUM(E4:E9995) -> 1.9473031e+09 | G3: Делта | H3: =+#REF!-H2 -> #REF!
A4: 46053 | B4: 342442112 | C4: Йил бошида карзим | E4: 89000000 | F4: тилло
B5: 955000 | C5: зарар 834 | E5: 3000000 | F5: пр
B6: 1270000 | C6: жамил | E6: 2100000 | F6: чермет
B7: =1250*12150 -> 15187500 | C7: хура | E7: 38900000 | F7: хитой
B8: =1200*12150 -> 14580000 | C8: рахим | E8: 1700000 | F8: 004 турон
B9: 200000 | C9: бобо | E9: 1300000 | F9: 966 навои
B10: 200000 | C10: уйга бозор | E10: 6000000 | F10: рахим
B11: 200000 | C11: икром с | E11: 1035360 | F11: шунчаки
B12: 2500000 | C12: олим к
B13: 1000000 | C13: усто ужин
A14: 2,02,2026 | B14: 12000000 | C14: дадем | E14: =63570*50 -> 3178500 | F14: 142,388,130 релс
B15: 1400000 | C15: фарход | E15: 900000 | F15: 264 нов
B16: 1205655 | C16: 266 зарар | E16: 800000 | F16: чермет
A17: 3,02,2026 | B17: 500000 | C17: наги | E17: 400000 | F17: 884 жамил
B18: 900000 | C18: гастинса | E18: =5000*2900 -> 14500000 | F18: сироч ака
B19: 700000 | C19: 966 зарар | E19: 1400000 | F19: 365 чугун
B20: =321604+88500 -> 410104 | C20: акумлатр | E20: 800000 | F20: 377 бозорбой
B21: 1000000 | C21: доллор | E21: 900000 | F21: 904 ислом
B22: 2400000 | C22: 011 зарар | E22: =5000*250 -> 1250000 | F22: дакумент 5 тн
E23: =8244*100 -> 824400 | F23: исмат
A24: 4,03,2026 | B24: 150000 | C24: мойка | E24: 800000 | F24: ислом 725
B25: 800000 | C25: бозор | E25: 1400000 | F25: низом 074
B26: 200000 | C26: абед | E26: 3500000 | F26: низом газли 445
B27: 750000 | C27: бек апа | E27: 400000 | F27: бобир 574
B28: 400000 | C28: клик тахи | E28: 800000 | F28: бобир 463
B29: 190000 | C29: матерал | E29: 620000 | F29: комил 593
B30: =272671+224905 -> 497576 | C30: сироч 10 тн | E30: 1900000 | F30: турон 597
E31: 502111 | F31: фарод 413
E32: 1880000 | F32: 588 кг
A33: 5,02,2026 | B33: 300000 | C33: газ | E33: 600000 | F33: жора
B34: 100000 | C34: сартарош | E34: 900000 | F34: клик
B35: 100000 | C35: меличи | E35: 700000 | F35: 145 олот
B36: =1320*12250 -> 16170000 | C36: акфачи баня | E36: 600000 | F36: 437 олот
B37: 12200000 | C37: кадастр | E37: 2900000 | F37: 562 ром
E38: 400000 | F38: 032 еко
A39: 6,02,2026 | B39: =7541*3000 -> 22623000 | C39: каракул | E39: =+'тура ака'!Q28 -> 1147490 | F39: =+'тура ака'!E28 -> 996 ТУР МЯХКИ
B40: 100000 | C40: дори | E40: =+'тура ака'!Q29 -> 661538 | F40: =+'тура ака'!E29 -> 384 бекобод
...

Sheet Чермт Бонус
A1: Дата | B1: Тонн | C1: Приход | D1: расход | E1: Нима учун | F1: Разница
C2: =+SUM(C5:C9214) -> 0 | D2: =+SUM(D5:D9214) -> 0 | F2: =+SUM(F5:F9214) -> 0 | G2: Приход | H2: =+C2 -> 0
G3: Расход | H3: =+D2 -> 0
G4: Фойда | H4: =+H2-H3-H7-H8-H9-H10-H11-H12 -> 0
A5: 46235 | C5: =+B5*100 -> 0 | G5: Ойбек | H5: =+H4/2 -> 0
A6: =+A5+1 -> 46236 | C6: =+B6*100 -> 0 | G6: Тура ака | H6: =+H5 -> 0
A7: =+A6+1 -> 46237 | C7: =+B7*100 -> 0 | G7: ИКРОМ
A8: =+A7+1 -> 46238 | C8: =+B8*100 -> 0 | G8: Алишер
A9: =+A8+1 -> 46239 | C9: =+B9*100 -> 0 | G9: мурод
A10: =+A9+1 -> 46240 | C10: =+B10*100 -> 0
A11: =+A10+1 -> 46241 | C11: =+B11*100 -> 0
A12: =+A11+1 -> 46242 | C12: =+B12*100 -> 0
A13: =+A12+1 -> 46243 | C13: =+B13*100 -> 0
A14: =+A13+1 -> 46244 | C14: =+B14*100 -> 0
A15: =+A14+1 -> 46245 | C15: =+B15*100 -> 0
A16: =+A15+1 -> 46246 | C16: =+B16*100 -> 0
A17: =+A16+1 -> 46247 | C17: =+B17*100 -> 0
A18: =+A17+1 -> 46248 | C18: =+B18*100 -> 0
A19: =+A18+1 -> 46249 | C19: =+B19*100 -> 0
A20: =+A19+1 -> 46250 | C20: =+B20*100 -> 0
A21: =+A20+1 -> 46251 | C21: =+B21*100 -> 0
... A35: =+A34+1 -> 46265 | C35: =+B35*100 -> 0

Sheet Рахим
A1: Дата | B1: Ойбек берган пул | C1: Раим Юк | D1: Харажат | E1: Мелоч харажат | F1: Сотилди | H1: Дата | I1: Рахим пули | J1: рахим расход | K1: САБАБ | M1: Дата | N1: Ойбек юк берди | O1: Иззат пул берди | P1: САБАБ | R1: Дата | S1: Ойбек юк берди | T1: рахим киленти янги | U1: САБАБ
A2: Утган хафтадан Колган пул | B2: =60340000+10200000 -> 70540000 | C2: 10200000 | H2: =I3-J3 -> 5639500 | M2: =N3-O3 -> 101446000 | R2: =S3-T3 -> 0
A3: душанба | B3: 41500000 | C3: 27120000 | D3: 2200000 | I3: =+SUM(I4:I9995) -> 27539500 | J3: =+SUM(J4:J18) -> 21900000 | N3: =+SUM(N4:N9995) -> 517803000 | O3: =+SUM(O4:O9995) -> 416357000 | S3: =+SUM(S4:S9995) -> 0 | T3: =+SUM(T4:T9995) -> 0
A4: Сешанба | H4: 10,08,2026 | I4: 10880000 | J4: 6600000 | M4: 18,08,2026 | N4: 48523000
A5: Чоршанба | H5: 18,08,2026 | I5: 3652500 | J5: 1000000 | K5: 48523000 | N5: 160995000 | O5: 50000000
A6: Пайшанба | O6: 60000000
A7: Жума | H7: 23,08,2026 | I7: 6622000 | J7: 6500000 | M7: 20,08,2026 | O7: 80000000
A8: Шанба | H8: 30,08,2026 | I8: 6385000 | J8: 7800000 | L8: - | M8: 23,08,2026 | N8: 172885000 | O8: 70000000
A9: Якшанба | M9: 26,08,2026 | O9: =2900*11830 -> 34307000 | P9: 2900*11830 $
O10: 15000000 | P10: сум
B11: =+SUM(B2:B10)-E11 -> 112040000 | C11: =+SUM(C2:C10) -> 37320000 | D11: =+SUM(D2:D10) -> 2200000 | E11: =+SUM(E2:E10) -> 0 | F11: =+SUM(F2:F10) -> 0 | M11: 30,08,2026 | N11: 135400000 | O11: 65550000 | P11: пул
M12: 31,08,2026 | O12: 41500000
A15: Харажат | B15: =+D11 -> 2200000 | C15: хафталик
A16: Раим пулаш | B16: 5639500 | C16: рахим пули шунга ез
A17: Раим пуаш Ойбекба | B17: =+B16-B15 -> 3439500
A18: Остаток | B18: =B11-C11-D11 -> 72520000
A19: Остатка юк | B19: =C11-F11 -> 37320000 | K19: 2900
A20: Фойда | B20: =+F11-C11 -> -37320000 | K20: 15
A21: Рахим фойда | B21: =+B20/2 -> -18660000

Sheet Каракул
A1: Дата | B1: Каракул Приход | C1: Каракул Расход | D1: БНПЗ | E1: Корхоно | F1: Тонн
E2: 24 01 2025 | F2: 380
A3: 10,04,2026 | B3: 594 | C3: 594 | E3: 13 02 2025 | F3: 104
E4: 19 02 2025 | F4: 107
E5: 14 04 2025 | F5: 349
E6: 16 04 2025 | F6: 300
E7: 18 04 2025 | F7: 286
E8: 10 06 2025 | F8: 78
E9: 1 07 2025 | F9: 570
E10: 2 07 2025 | F10: 310
E11: 19 07 2025 | F11: 407
E12: 19 07 2025 | F12: 95
E13: 21 08 2025 | F13: 105
E14: 2 09 2025 | F14: 280
E15: 3 09 2025 | F15: 7
... E21: 24 11 2025 | F21: 256
E22: 8689 кг
D25: 95
E28: 31,01,2026 СИРОЧ АКА | F28: 15000
E29: 3,02,2026 сироч ака | F29: 5000
E30: 06,02,2026 сирож ака | F30: 5000
E31: 10,02,2026 СИРОЧ АКА | F31: 5000
E32: 21,02,2026 сироч ака | F32: 10000
B51: =+SUM(B2:B50) -> 594 | C51: =+SUM(C2:C50) -> 594 | D51: =+SUM(D2:D50) -> 95 | F51: =+SUM(F2:F50) -> 48689
B53: Каракул | C53: =+B51-C51 -> 0
B54: Бнпз | C54: =+D51 -> 95
B55: Корхоно | C55: =+F51 -> 48689
B56: Итого | C56: =+SUM(C53:C55) -> 48784 | D56: =+C56*2900 -> 141473600

Sheet тогом
A1: Дата | B1: Ойбек пул берди | C1: Тогом юк берди | D1: Сабаб
A2: =B3-C3 -> -14976200
B3: =+SUM(B4:B10022) -> 1158731600 | C3: =+SUM(C4:C10022) -> 1173707800
A4: 28,02,2026 | C4: =4650*3600 -> 16740000 | D4: 4650*3600
A5: 5,03,2026 | B5: 16470000 | D5: мухи
B6: =750*3000 -> 2250000 | D6: 750*3 чугун
C7: =11590*3500 -> 40565000 | D7: 11590*3500
A8: 7,03,2026 | B8: =2500*12150 -> 30375000 | D8: 2500*12150
A9: 8,03,2026 | B9: 20000000 | C9: =9480*3500 -> 33180000 | D9: 9480*3500
A10: 10,03,2026 | B10: 22000000 | C10: =7780*3500 -> 27230000 | D10: 449 мошин,
A11: 11,03,2026 | C11: =4530*3200 -> 14496000 | D11: 4530*3200
A12: 12,03,2026 | B12: =1500*12100 -> 18150000 | C12: =4900*3600 -> 17640000 | D12: 4900*3600
A13: 13,03,2026 | B13: 24100000 | D13: 2000*12050
A14: 16,03,2026 | C14: =3930*3600 -> 14148000 | D14: 3930*3600
A15: 17,03,2026 | B15: 12050000 | C15: =4920*3600 -> 17712000 | D15: 1000*12050
A16: 18,03,2026 | B16: 25000000
A17: 19,03,2026 | C17: =5080*3600 -> 18288000 | D17: 5080*3600
A18: 21,03,2026 | C18: =4420*3600 -> 15912000 | D18: 4420*3600
A19: 22,03,2026 | B19: 12150000 | D19: 1000 $
A20: 23,03,2026 | B20: =2000*12050 -> 24100000 | D20: $ 2000*12050
C21: =5000*3600 -> 18000000 | D21: 5000*3600 мяхки
A22: 30,03,2026 | C22: =5180*3200 -> 16576000 | D22: 5180*3200
A23: 4,04,2026 | B23: 16000000 | D23: сум
C24: 3000000 | D24: релс
A25: 11,04,2026 | C25: =126*3500 -> 441000 | D25: 126 кг
A26: 15,04,2026 | C26: =4400*3600 -> 15840000 | D26: 4400*3600
A27: 16,04,2026 | B27: 7000000
B28: =1300*12150 -> 15795000
A29: 17,04,2026 | C29: =3580*3600 -> 12888000 | D29: 3580*3600
A30: 18,04,2026 | B30: =1500*12140 -> 18210000
A31: 19,04,2026 | C31: =4680*3600 -> 16848000 | D31: 4680*3600
A32: 21,04,2026 | B32: 20000000 | D32: СУМ
A33: 22,04,2026 | B33: 20000000 | C33: =6480*3600 -> 23328000 | D33: 6480*3600
A34: 23,04,2026 | C34: =4370*3200 -> 13984000 | D34: 4370*3200
A35: 23,04,2026 | C35: =4940*3600 -> 17784000 | D35: 4940*3600
A36: 25,04,2026 | B36: 30000000 | C36: =4080*3600 -> 14688000 | D36: 4080*3600
A37: 27,04,2026 | B37: 12000000 | D37: 1000*12000 $
A38: 29,04,2026 | B38: 2520000 | D38: ФАРУГ
A39: 30,04,2026 | C39: =10150*3500 -> 35525000 | D39: 10150*3500 | E39: 3700$ ТОГОМ
A40: 30,04,2026 | B40: 23900000 | D40: 2000$ | E40: 300$ Ойбек | G40: 5,05,2026
...

Sheet Гостиница
A1: Дата | B1: Расход сумма | C1: Расход Наименование
B3: Жами Расход | C3: =+SUM(B4:B10040) -> 0
A5: Итого | C5: =340645+22828+17092+30606+C14 -> 429829
C6: 2022-2025 расход 293,000 $$$
A7: 31,01,2026 | C7: 14242
A8: 28,02,2026 | C8: =214150000/12150 -> 17625.514
A9: 31,03,2026 | C9: $15 777
A10: 31,03,2026 | C10: 568,820,000__ 46624$
A11: 30,04,26 | C11: 22828
A12: 31,05,26 | C12: 17092
A13: 46203 | C13: 30606
A14: 46234 | C14: 18658
C15: 430,000 $ обши расход
C21: саехат 24000000
C22: 900 $ 10,000,000
C23: бохча 1500,000

Sheet Бонусча
C2: Сабаб | D2: Ойбек | E2: ТОНН | F2: Цена | G2: Хитой бонусча
D3: =+SUM(D4:D34) -> 0 | E3: =+SUM(E4:E34) -> 0 | G3: =+SUM(G4:G34) -> 0 | H3: Ойбек пул берди | I3: =+D3 -> 0
B4: 46204 | G4: =+E4*F4 -> 0 | H4: =+G2 -> Хитой бонусча | I4: =+G3 -> 0
B5: =+B4+1 -> 46205 | G5: =+E5*F5 -> 0
B6: =+B5+1 -> 46206 | G6: =+E6*F6 -> 0
B7: =+B6+1 -> 46207 | G7: =+E7*F7 -> 0 | H7: Делта | I7: =+I3-I4+I5 -> 0
B8: =+B7+1 -> 46208 | G8: =+E8*F8 -> 0
B9: =+B8+1 -> 46209 | G9: =+E9*F9 -> 0
B10: =+B9+1 -> 46210 | G10: =+E10*F10 -> 0
B11: =+B10+1 -> 46211 | G11: =+E11*F11 -> 0
B12: =+B11+1 -> 46212 | G12: =+E12*F12 -> 0
B13: =+B12+1 -> 46213 | G13: =+E13*F13 -> 0
B14: =+B13+1 -> 46214 | G14: =+E14*F14 -> 0
B15: =+B14+1 -> 46215 | G15: =+E15*F15 -> 0
B16: =+B15+1 -> 46216 | G16: =+E16*F16 -> 0
B17: =+B16+1 -> 46217 | G17: =+E17*F17 -> 0
B18: =+B17+1 -> 46218 | G18: =+E18*F18 -> 0
B19: =+B18+1 -> 46219 | G19: =+E19*F19 -> 0
... B34: =+B33+1 -> 46234 | G34: =+E34*F34 -> 0

Sheet Чугун
B2: № | C2: Дата | D2: Сабаб | E2: Райим пул берди | F2: Рахим расход | G2: Мошин номер | H2: Брутто | I2: Нетто | J2: ТОНН | K2: Скидка | L2: После скидка | M2: Цена | N2: Навои Металл | O2: Тура ака
E3: =+SUM(E4:E13) -> 0 | F3: =+SUM(F4:F13) -> 0 | J3: =+SUM(J4:J16) -> 0 | L3: =+SUM(L4:L16) -> 0 | N3: =+SUM(N4:N16) -> 0 | O3: =+SUM(O4:O16) -> 0
B4: 1 | J4: =+H4-I4 -> 0 | L4: =+J4-(J4*K4/100) -> 0 | N4: =+(J4-J4*K4/100)*M4 -> 0
B5: 2 | J5: =+H5-I5 -> 0 | L5: =+J5-(J5*K5/100) -> 0 | N5: =+(J5-J5*K5/100)*M5 -> 0
B6: =+B5+1 -> 3 | J6: =+H6-I6 -> 0 | L6: =+J6-(J6*K6/100) -> 0 | N6: =+(J6-J6*K6/100)*M6 -> 0
B7: =+B6+1 -> 4 | J7: =+H7-I7 -> 0 | L7: =+J7-(J7*K7/100) -> 0 | N7: =+(J7-J7*K7/100)*M7 -> 0
B8: =+B7+1 -> 5 | J8: =+H8-I8 -> 0 | L8: =+J8-(J8*K8/100) -> 0 | N8: =+(J8-J8*K8/100)*M8 -> 0
B9: =+B8+1 -> 6 | J9: =+H9-I9 -> 0 | L9: =+J9-(J9*K9/100) -> 0 | N9: =+(J9-J9*K9/100)*M9 -> 0
B10: =+B9+1 -> 7 | J10: =+H10-I10 -> 0 | L10: =+J10-(J10*K10/100) -> 0 | N10: =+(J10-J10*K10/100)*M10 -> 0
B11: =+B10+1 -> 8 | J11: =+H11-I11 -> 0 | L11: =+J11-(J11*K11/100) -> 0 | N11: =+(J11-J11*K11/100)*M11 -> 0
B12: =+B11+1 -> 9 | J12: =+H12-I12 -> 0 | L12: =+J12-(J12*K12/100) -> 0 | N12: =+(J12-J12*K12/100)*M12 -> 0
B13: =+B12+1 -> 10 | J13: =+H13-I13 -> 0 | L13: =+J13-(J13*K13/100) -> 0 | N13: =+(J13-J13*K13/100)*M13 -> 0
B14: =+B13+1 -> 11 | J14: =+H14-I14 -> 0 | L14: =+J14-(J14*K14/100) -> 0 | N14: =+(J14-J14*K14/100)*M14 -> 0
B15: =+B14+1 -> 12 | J15: =+H15-I15 -> 0 | L15: =+J15-(J15*K15/100) -> 0 | N15: =+(J15-J15*K15/100)*M15 -> 0
B16: =+B15+1 -> 13 | J16: =+H16-I16 -> 0 | L16: =+J16-(J16*K16/100) -> 0 | N16: =+(J16-J16*K16/100)*M16 -> 0
C17: Ойбек пул берди | D17: =+E3 -> 0
C18: =+N2 -> Навои Металл | D18: =+N3 -> 0
C19: Рахим НАВОИ | D19: =+D17-D18 -> 0
C20: Металл сотилди | D20: =+O3 -> 0
C21: =+F2 -> Рахим расход | D21: =+F3 -> 0
C22: Делта | D22: =+D20-D18-D21 -> 0
B26: № | C26: Дата | D26: Сабаб | E26: Сумма Олинди | F26: Мошин номер | G26: Мошин пули | H26: Брутто | I26: Нетто | J26: ТОНН | K26: Скидка | L26: После скидка | M26: Цена | N26: Чугун
E27: =+SUM(E28:E37) -> 0 | F27: 200 | G27: =+SUM(G28:G40) -> 0 | J27: =+SUM(J28:J40) -> 0 | L27: =+SUM(L28:L40) -> 0 | N27: =+SUM(N28:N40) -> 0 | O27: Тура ака пул берди | P27: =+E27 -> 0
B28: 1 | G28: =+J28*9 -> 0 | J28: =+H28-I28 -> 0 | L28: =+J28-(J28*K28/100) -> 0 | N28: =+(J28-J28*K28/100)*M28 -> 0 | O28: =+N26 -> Чугун | P28: =+N27 -> 0
B29: 2 | G29: =+J29*9 -> 0 | J29: =+H29-I29 -> 0 | L29: =+J29-(J29*K29/100) -> 0 | N29: =+(J29-J29*K29/100)*M29 -> 0 | O29: Делта | P29: =+P27-P28 -> 0
B30: =+B29+1 -> 3 | G30: =+J30*9 -> 0 | J30: =+H30-I30 -> 0 | L30: =+J30-(J30*K30/100) -> 0 | N30: =+(J30-J30*K30/100)*M30 -> 0
B31: =+B30+1 -> 4 | G31: =+J31*9 -> 0 | J31: =+H31-I31 -> 0 | L31: =+J31-(J31*K31/100) -> 0 | N31: =+(J31-J31*K31/100)*M31 -> 0
B32: =+B31+1 -> 5 | G32: =+J32*9 -> 0 | J32: =+H32-I32 -> 0 | L32: =+J32-(J32*K32/100) -> 0 | N32: =+(J32-J32*K32/100)*M32 -> 0
B33: =+B32+1 -> 6 | G33: =+J33*9 -> 0 | J33: =+H33-I33 -> 0 | L33: =+J33-(J33*K33/100) -> 0 | N33: =+(J33-J33*K33/100)*M33 -> 0
B34: =+B33+1 -> 7 | G34: =+J34*9 -> 0 | J34: =+H34-I34 -> 0 | L34: =+J34-(J34*K34/100) -> 0 | N34: =+(J34-J34*K34/100)*M34 -> 0
B35: =+B34+1 -> 8 | G35: =+J35*9 -> 0 | J35: =+H35-I35 -> 0 | L35: =+J35-(J35*K35/100) -> 0 | N35: =+(J35-J35*K35/100)*M35 -> 0
B36: =+B35+1 -> 9 | G36: =+J36*9 -> 0 | J36: =+H36-I36 -> 0 | L36: =+J36-(J36*K36/100) -> 0 | N36: =+(J36-J36*K36/100)*M36 -> 0
B37: =+B36+1 -> 10 | G37: =+J37*9 -> 0 | J37: =+H37-I37 -> 0 | L37: =+J37-(J37*K37/100) -> 0 | N37: =+(J37-J37*K37/100)*M37 -> 0
B38: =+B37+1 -> 11 | G38: =+J38*9 -> 0 | J38: =+H38-I38 -> 0 | L38: =+J38-(J38*K38/100) -> 0 | N38: =+(J38-J38*K38/100)*M38 -> 0
B39: =+B38+1 -> 12 | G39: =+J39*F27 -> 0 | J39: =+H39-I39 -> 0 | L39: =+J39-(J39*K39/100) -> 0 | N39: =+(J39-J39*K39/100)*M39 -> 0
B40: =+B39+1 -> 13 | G40: =+J40*F27 -> 0 | J40: =+H40-I40 -> 0 | L40: =+J40-(J40*K40/100) -> 0 | N40: =+(J40-J40*K40/100)*M40 -> 0
